Workbook

Sheet Read Me
A1: Baumarkt-Buddy – Feature Implementation Plan
A2: v0.9 · 29 Oct 2026 · basis: requirements and test cases updated with the team decisions of 29 Oct 2026
A4: What is this? | B4: All product features, the release they belong to, and whether they are built. Each feature links to its requirements and tests.
A5: Basis | B5: requirements-R1-MVP_2026-10-27.md (53 requirements) · requirements-R2-R4_2026-10-27.md (18) · 01_test_cases_2026-10-27.md (v1.2) – all updated with the team decisions of 29 Oct 2026.
A6: How to read it | B6: Sheet "Features": one row per feature. Status: Built · Partly built · Not built · Planned (later release). Column "Decision" points to the discussion list.
A7: Decisions | B7: Sheet "Discussion": D-1 … D-12 with the team decision (29 Oct 2026), the result and where the files changed. Undecided: D-6, D-12. D-10: to verify with the vibe coder.
A8: Other sheets | B8: Traceability (every requirement → feature → tests) · Documents · Version history.
A9: To build | B9: Notes with "To build" = decided on 29 Oct 2026, not yet in the app.

Sheet Features
A1: Features
A2: Green = built · yellow = partly built · orange = not built · blue = later release
A4: Feature | B4: Name | C4: What the customer gets | D4: Release | E4: MoSCoW | F4: Status | G4: Requirements | H4: Tests | I4: Release-blocking tests | J4: Decision | K4: Note
A5: F-01 | B5: Describe the project by typing or with a project button | C5: Type what you want to do or tap one of the 9 project buttons. | D5: R1 | E5: Must | F5: Built | G5: FR-02, FR-03, NFR-03 | H5: TC-001, TC-002, TC-003, TC-004, TC-050, TC-051, TC-052, TC-053, TC-099, UT-09 | I5: – | J5: –
A6: F-02 | B6: Describe the project by speaking | C6: Say what you want to do; check the text before it is used. | D6: R1 | E6: Must | F6: Built | G6: FR-25, FR-27, SR-11 | H6: RT-08, TC-005, TC-006, TC-007, TC-008, TC-027, TC-052, TC-056, TC-064, UT-01 | I6: RB-18, RB-19, RB-20 | J6: –
A7: F-03 | B7: Questions and confirmed facts | C7: Max. 3 question screens; only confirmed facts are used. | D7: R1 | E7: Must | F7: Built | G7: FR-04, FR-05, SR-01, SR-06 | H7: RT-05, TC-004, TC-007, TC-010, TC-014, TC-015, TC-016, TC-017, TC-027, TC-030, TC-032, TC-035, TC-044, TC-085, TC-094, TC-097, TC-104, TC-105, TC-106, UT-01, UT-04 | I7: – | J7: D-8 | K7: FR-05 = max. 3 question screens (D-8).
A8: F-04 | B8: Checked shopping list | C8: List in Materials / Tools / Safety gear where all parts fit together. | D8: R1 | E8: Must | F8: Built | G8: FR-06, FR-08, FR-09, SR-03, SR-04, SR-07, SR-08 | H8: RT-06, RT-07, TC-012, TC-013, TC-018, TC-019, TC-020, TC-021, TC-025, TC-029, TC-030, TC-031, TC-032, TC-036, TC-037, TC-038, TC-039, TC-045, TC-069, TC-080, TC-083, TC-084, TC-086, TC-087, TC-088, TC-089, TC-096, TC-105, UT-04, UT-05, UT-06, UT-07, UT-08, UT-10, UT-11 | I8: RB-01, RB-03, RB-04, RB-08, RB-13 | J8: –
A9: F-05 | B9: Safety stops and hand-off | C9: Dangerous jobs are refused with "hire a professional" or "ask staff". | D9: R1 | E9: Must | F9: Built | G9: FR-15, SR-02, SR-05, SR-09 | H9: RT-01, RT-02, RT-03, RT-04, RT-08, TC-026, TC-028, TC-033, TC-034, TC-040, TC-041, TC-042, TC-044, TC-082, TC-085, TC-086, TC-087, TC-089, TC-093, TC-095 | I9: RB-07 | J9: –
A10: F-06 | B10: Optional postcode (PLZ) and store choice | C10: Enter a postcode (optional); stores nearest first; you pick one. | D10: R1 | E10: Must | F10: Built | G10: FR-29, FR-30, DR-08 | H10: TC-009, TC-010, TC-011, TC-012, TC-013, TC-053, TC-055, TC-077, TC-078, TC-107, UT-02, UT-03, UT-12 | I10: RB-16, RB-17 | J10: D-8, D-11 | K10: Decided: 50 km, 6 stores incl. OBI Schwabach (D-8, D-11). Schwabach to add to the data.
A11: F-07 | B11: Price, stock, aisle and shelf; referral if missing | C11: See price, stock, aisle and shelf; a missing part names the nearest store that has it. | D11: R1 | E11: Must | F11: Built | G11: FR-11, FR-31 | H11: TC-022, TC-023, TC-024, TC-025, TC-079, UT-10 | I11: RB-06, RB-15, RB-21 | J11: D-9 | K11: Without a postcode: price shown, stock / aisle / shelf "not available" (built; written into FR-30, D-9).
A12: F-08 | B12: Sample data and team review | C12: One data workbook (105 products, 5 stores); projects checked by the team. | D12: R1 | E12: Must | F12: Built | G12: DR-01, DR-02, DR-03, DR-07, NFR-10, SR-10 | H12: TC-020, TC-022, TC-023, TC-024, TC-043, TC-059, TC-066, TC-067, TC-068, TC-069, TC-070, TC-071, TC-076, TC-079, TC-096, TC-098, TC-099, TC-106, TC-107, UT-12 | I12: – | J12: – | K12: Team review of the 9 projects: finalised (28 Oct 2026).
A13: F-09 | B13: Trust, privacy and security | C13: AI is labelled, no login, minimal data, hidden instructions are ignored. | D13: R1 | E13: Must | F13: Built | G13: NFR-04, NFR-05, NFR-06, NFR-07, DR-05 | H13: RT-05, RT-06, RT-07, TC-010, TC-051, TC-054, TC-055, TC-056, TC-057, TC-058, TC-059, TC-060, TC-061, TC-062, TC-063, TC-064, TC-074, TC-075, TC-092, TC-101, TC-104, UT-08, UT-09 | I13: RB-09 | J13: –
A14: F-10 | B14: Mobile use, speed and language | C14: List in under 2 minutes on a phone, in German or English. | D14: R1 | E14: Must | F14: Built | G14: NFR-01, NFR-02, NFR-09, NFR-12 | H14: TC-002, TC-006, TC-015, TC-046, TC-047, TC-048, TC-049, TC-065, TC-093, TC-098 | I14: – | J14: – | K14: Speech checked by Hari (28 Oct 2026): works in Chrome, Edge, Safari and on phones.
A15: F-11 | B15: Project catalogue: 9 projects with limits and stop rules | C15: Shelf, wall cabinet, picture, anti-tip, paint, glass door, door lock, sliding door, wallpaper – each with its own limits. | D15: R1 | E15: Must | F15: Built | G15: DR-04, SR-13 | H15: TC-019, TC-043, TC-072, TC-073, TC-080, TC-081, TC-082, TC-083, TC-084, TC-085, TC-086, TC-087, TC-088, TC-089, TC-093, TC-096, TC-097, TC-099, TC-105, TC-106 | I15: RB-22 | J15: D-4, D-5, D-6, D-7, D-8, D-10 | K15: Decided: sliding door 40 kg (D-4); wood and aerated concrete in R1 (D-5, to build). Open: sliding-door rules (D-6), drop-downs (D-10, to verify with the vibe coder).
A16: F-12 | B16: OBI how-to links | C16: Checked OBI videos and articles for projects 5–9. | D16: R1 | E16: Should | F16: Built | G16: FR-32 | H16: TC-092 | I16: – | J16: D-8 | K16: All videos verified by Hari (D-8).
A17: F-13 | B17: Weight and condition check | C17: Give the weight; used parts are checked for damage. | D17: R1 | E17: Must | F17: Partly built | G17: FR-33, SR-14 | H17: TC-091, TC-094, TC-104 | I17: RB-23 | J17: D-2 | K17: Decided (D-2): "weigh it", "estimate for me", unknown → worst case. To build.
A18: F-14 | B18: One safety check per project | C18: Easy projects (painting) get no wall or weight questions; all safety checks still run. | D18: R1 | E18: Must | F18: Built | G18: SR-16 | H18: TC-084, TC-095 | I18: RB-25 | J18: D-7
A19: F-15 | B19: Owned items on the shopping list | C19: Mark "I already have this"; the price leaves the section subtotal and the total. | D19: R1 | E19: Must | F19: Partly built | G19: FR-07, FR-34, SR-15, SR-17 | H19: TC-090, TC-091, TC-102, TC-103 | I19: RB-24 | J19: D-3, D-7 | K19: Decided (D-3): tick box removed; "I already have this" only; subtotal per section (FR-34); hint for own tools and safety gear (SR-17); plugs and screws always new. To build.
A20: F-16 | B20: Save the project list | C20: Save the complete list (products, prices, aisle and shelf, how-to links) on the phone and share it. | D20: R1 | E20: Must | F20: Not built | G20: FR-17, DR-06 | H20: TC-100, TC-101 | I20: – | J20: D-1 | K20: Decided (D-1): R1 / Must. To build.
A21: F-17 | B21: Explanations | C21: Why each part fits and what is still unknown. | D21: R2 | E21: Must | F21: Planned | G21: FR-10 | H21: – | I21: – | J21: – | K21: Part already in R1 (evidence log, stop texts).
A22: F-18 | B22: Cheaper or better alternatives | C22: Other options for an item, with a new total. | D22: R2 | E22: Should | F22: Planned | G22: FR-12 | H22: – | I22: – | J22: – | K22: Variant switch already in R1.
A23: F-19 | B23: Offline checklist | C23: The list works in the store without internet. | D23: R2 | E23: Should | F23: Planned | G23: FR-14 | H23: – | I23: RB-05, RB-12 | J23: –
A24: F-20 | B24: Step-by-step assembly guide | C24: Building steps based on the manufacturer's manual. | D24: R2 | E24: Should | F24: Planned | G24: FR-16 | H24: – | I24: – | J24: – | K24: R1 has the OBI links only.
A25: F-21 | B25: Accessibility | C25: Good contrast, bigger text, screen readers. | D25: R2 | E25: Should | F25: Planned | G25: NFR-08 | H25: – | I25: – | J25: –
A26: F-22 | B26: Save and resume a project | C26: Come back to a project later. | D26: R3 | E26: Should | F26: Planned | G26: FR-01 | H26: – | I26: – | J26: –
A27: F-23 | B27: Describe the project with a photo | C27: Upload a photo; the app treats what it sees as a guess to confirm. | D27: R3 | E27: Must | F27: Planned | G27: FR-26, FR-28, SR-12 | H27: – | I27: RB-02 | J27: –
A28: F-24 | B28: Store search and hand-off to staff | C28: Pass the list to the store or a store employee. | D28: R3 | E28: Should | F28: Planned | G28: FR-13, FR-22 | H28: – | I28: RB-11 | J28: –
A29: F-25 | B29: Verified aisle locations | C29: Checked aisle and shelf in a real store. | D29: R3 | E29: Should | F29: Planned | G29: FR-18 | H29: – | I29: – | J29: –
A30: F-26 | B30: Scan products and track assembly | C30: Scan a product in the store; follow the building steps. | D30: R3 | E30: Could | F30: Planned | G30: FR-19, FR-20 | H30: – | I30: RB-14 | J30: –
A31: F-27 | B31: Room visualisation | C31: See a picture of the finished project. | D31: R3 | E31: Could | F31: Planned | G31: FR-24 | H31: – | I31: – | J31: –
A32: F-28 | B32: Monitoring | C32: Track problems, waiting times and costs. | D32: R3 | E32: Should | F32: Planned | G32: NFR-11 | H32: – | I32: – | J32: –
A33: F-29 | B33: Reservation and cross-retailer baskets | C33: Reserve products; compare stores. | D33: Beyond | E33: Won't | F33: Not planned | G33: FR-21, FR-23 | H33: – | I33: RB-10 | J33: –
A35: Count
B36: Built | C36: =COUNTIF($F$5:$F$33,B36) -> 13
B37: Partly built | C37: =COUNTIF($F$5:$F$33,B37) -> 2
B38: Not built | C38: =COUNTIF($F$5:$F$33,B38) -> 1
B39: Planned | C39: =COUNTIF($F$5:$F$33,B39) -> 12
B40: Not planned | C40: =COUNTIF($F$5:$F$33,B40) -> 1
B41: Total | C41: =SUM(C36:C40) -> 29

Sheet Discussion
A1: Discussion list – team decisions of 29 Oct 2026
A2: Column H = team decision · column J = where the requirements and test cases changed
A4: No. | B4: Topic | C4: Feature | D4: App today (colleague) | E4: Our proposal | F4: Why | G4: Risk | H4: Decision (29 Oct 2026) | I4: Result | J4: Changed in
A5: D-1 | B5: Save the project list | C5: F-16 | D5: Not built. Requirement file says R2 / Could. | E5: R1 / Must: save the complete list (products, prices, aisle and shelf, how-to links) on the phone and share it. | F5: Agreed by Hari and the colleague – please confirm. | G5: None | H5: In R1 as Must | I5: Decided | J5: Requirements: FR-17, DR-06 moved to R1 / Must · Tests: TC-100, TC-101
A6: D-2 | B6: Unknown weight | C6: F-13 | D6: "I don't know" → the app stops. | E6: Add "weigh it" (bathroom-scale tip) and "estimate for me" (shown as estimate, customer confirms); unknown → worst case. | F6: Helps customers with second-hand items. | G6: A little less strict; estimate values need a team review. | H6: Proposal Approved. | I6: Decided | J6: Requirements: FR-04, SR-14 · Tests: TC-094 (changed), TC-104, RB-23
A7: D-3 | B7: Owned items and prices | C7: F-15 | D7: Two controls: a tick box on every item (shopping checklist – price does not change) and an "I already have this" button for tools and load-bearing parts (price leaves the total). No subtotal per section. Plugs and screws: no button, no hint. | E7: (a) An item the customer already has is ticked off and its price is deducted from the section subtotal and the total. (b) Each section (Materials, Tools, Safety gear) shows its subtotal. (c) Plugs and screws: allow with the hint "must suit your wall type and the size on the list" – or keep "always new". | F7: One clear rule; full price transparency. | G7: (a), (b): none. (c): less strict – keeping "always new" is safer. | H7: Remove the tick box and keep "I already have this" button. Add total price of sub categories. Add if needed a requirement that looks if an item removed from checked list using the button "I already have this", and check if the item is safety gear or a tool. If so a hint is given that "Keep the right tool and gear to ensure safety". | I7: Decided | J7: Requirements: FR-07, FR-34 (new), SR-15, SR-17 (new) · Tests: TC-090 (changed), TC-102, TC-103
A8: D-4 | B8: Sliding door weight | C8: F-11 | D8: Max. 40 kg (plug 50 kg ÷ 1.25). | E8: 60 kg, but only after a plug or anchor rated at least 75 kg is in the catalogue. | F8: Covers heavier doors. | G8: Unsafe without the stronger plug. | H8: Proposal Approved. | I8: Decided | J8: Requirements: SR-13 (rationale) · Tests: §9 item 10
A9: D-5 | B9: Wood and aerated concrete walls in R1 | C9: F-11 | D9: Wood: not offered. Aerated concrete: offered, but the app always stops ("ask staff") – no suitable plugs in the catalogue. | E9: Full feature in R1 for all mounting projects: (1) product catalogue: add aerated-concrete plugs (generic sample products) and mark wood screws P048–P050 for wood; (2) project catalogue: limits for both walls (wood max. 50 kg; aerated concrete = rating of the new plug ÷ 1.25), drill and bit per wall, items; (3) app templates and tests. If not ready for R1: do not offer the two wall types at all. | F9: Customers with these walls get real help. | G9: New limits need a team review. Effort about 1.5–2 person-days. | H9: Proposal Approved. | I9: Decided | J9: Requirements: FR-03, FR-04, SR-13, DR-01 · Tests: TC-097 (changed), TC-105, TC-106
A10: D-6 | B10: Sliding-door rules | C10: F-11 | D10: In the app only: 3 cm overlap per side and at the top, free wall beside the opening. | E10: Write them into the project catalogue as "assumption". | F10: One source for all limits. | G10: None – only confirm. | H10: Undecided | I10: Undecided | J10: No change (undecided)
A11: D-7 | B11: Three extra release tests | C11: F-11, F-14, F-15 | D11: The behaviour is tested, but not as release-blocking tests. | E11: RB-22: every limit just below / at / above (e.g. plasterboard 25 kg → list, 25.1 kg → stop; tested by TC-081, 082, 089, 096). RB-24: ticked-off item stays visible, subtotals and total correct (extend TC-090 after D-3). RB-25: an easy project never skips safety checks ("paint the wall and move the socket" → stop; TC-095). | F11: The release only goes out when these pass. | G11: None. | H11: Proposal Approved. Add these test in the file "01_test_cases_2026-10-27.md". | I11: Decided | J11: Tests: RB-22, RB-24, RB-25 in §7.1 (19 gates)
A12: D-8 | B12: Text updates | C12: F-03, F-06, F-11, F-12 | D12: Some texts in the files no longer match the app. | E12: FR-05: "on at most 3 question screens" · FR-29: 50 km, max. 5 stores shown, 5 sample stores · FR-31: TC-024, TC-079 instead of TC-34…TC-37 · DR-04: 9 reviewed project templates · project catalogue: all videos verified (Hari) · test cases §9: Q-1…Q-4 resolved · app test names: new test IDs (developer). | F12: Documents match the app. | G12: None – only confirm. | H12: Proposal Approved. | I12: Decided | J12: Requirements: FR-05, FR-29, FR-31, FR-32, DR-04 · Tests: §9
A13: D-9 | B13: Price and stock without a postcode | C13: F-07 | D13: Built: price shown; stock, aisle and shelf "not available" with the hint to add a postcode. FR-30 still says "TBD". | E13: No new requirement – write the app behaviour into FR-30. | F13: Requirement matches the app. | G13: None – only confirm. | H13: Proposal Approved. Write the app behaviour into FR-30. | I13: Decided | J13: Requirements: FR-30 · Tests: §9 item 4
A14: D-10 | B14: Show the allowed range at each input field | C14: F-11 | D14: Limits are checked only after all answers: the customer fills in everything and then sees "we stop here for safety". | E14: Show the permissible range as a clear note beside each dimension or weight field (e.g. "Weight: max. 25 kg on plasterboard", "Depth: max. 30 cm"); the note follows earlier answers (e.g. wall type). New requirement – EN: "Display the permissible range for each dimension or physical specification as a clear note beside the corresponding input field, so customers know the safety limits before making their selection." DE: "Der zulässige Bereich jeder Abmessung oder physikalischen Angabe wird als deutlicher Hinweis neben dem jeweiligen Eingabefeld angezeigt, damit Kunden die Sicherheitsgrenzen vor ihrer Auswahl kennen." | F14: No disappointment at the end; customers choose within the limits. | G14: None – the stop rules stay as they are. | H14: 1. Use a drop down option for possible length and width,citing the standrad dimensions (30, 50, 60, 75, 90, 100, 120cm). 2. And for weight it is also a drop down with a min and maximum value. | I14: Decided – to verify with the vibe coder | J14: No change yet – requirement after verification with the vibe coder (noted in R1 summary and tests §9)
A15: D-11 | B15: Add OBI Schwabach as 6th store | C15: F-06 | D15: 5 sample stores (Nürnberg, Erlangen). | E15: Add OBI Markt Schwabach, Nürnberger Str. 86, 91126 Schwabach, Mo–Sa 8:00–20:00 (one persona lives there). Update the Stores and Store stock sheets (sample stock for all 105 products), "max. stores shown" from 5 to 6, DR-01 and FR-29 texts, and the tests that count 5 stores. | F15: Matches our persona. | G15: None for safety; tests must be updated. | H15: Proposal Approved. | I15: Decided | J15: Requirements: DR-01, FR-29 · Tests: TC-107, fixture 6 stores
A16: D-12 | B16: Update the design document (03-design.md) | C16: all | D16: Still v0.4 (25 Oct): 70 products, 5 stores, old CSV files, rules only for shelf and picture, templates "to be created"; DD-6 and DD-8 already built. Not used for the vibe coding. | E16: Bring it to v0.5 after this meeting, based on the app and today's decisions: 9 projects and safety levels, stop rules ST-01…ST-14, owned items, how-to links, range notes (D-10), 6 stores, rule table, data sources. Decide who and by when. | F16: Completes the V-model design phase. | G16: None – documentation only. | H16: Undecided | I16: Undecided | J16: No change (undecided)

Sheet Traceability
A1: Traceability – requirement → feature → tests
A2: Requirements and tests exactly as in the files of 27 Oct 2026 · release and MoSCoW from the requirement files
A4: Req. ID | B4: Type | C4: Requirement | D4: Release | E4: MoSCoW | F4: Team decision (file) | G4: Feature | H4: Feature name | I4: Tests | J4: Requirement file | K4: Note
A5: FR-02 | B5: Functional | C5: Describe the project using a free-text description | D5: R1 | E5: Must | F5: Discuss | G5: F-01 | H5: =IFERROR(INDEX(Features!$B$5:$B$33,MATCH(G5,Features!$A$5:$A$33,0)),"not mapped") -> Describe the project by typing or with a project button | I5: TC-001, TC-002, TC-003, TC-099 | J5: requirements-R1-MVP_2026-10-27.md
A6: FR-03 | B6: Functional | C6: Classify project intent and extract candidate project description | D6: R1 | E6: Must | F6: Discuss | G6: F-01 | H6: =IFERROR(INDEX(Features!$B$5:$B$33,MATCH(G6,Features!$A$5:$A$33,0)),"not mapped") -> Describe the project by typing or with a project button | I6: TC-001, TC-002, TC-003, TC-004, TC-099 | J6: requirements-R1-MVP_2026-10-27.md | K6: Changed 29 Oct 2026
A7: FR-04 | B7: Functional | C7: Capture measurements, units, constraints and owned items | D7: R1 | E7: Must | F7: Accept | G7: F-03 | H7: =IFERROR(INDEX(Features!$B$5:$B$33,MATCH(G7,Features!$A$5:$A$33,0)),"not mapped") -> Questions and confirmed facts | I7: TC-007, TC-014, TC-015, TC-097, TC-104, TC-105, TC-106 | J7: requirements-R1-MVP_2026-10-27.md | K7: Changed 29 Oct 2026
A8: FR-05 | B8: Functional | C8: Ask dependency-aware follow-up questions on at most 3 question screens; a screen may hold several questions if the project needs them. | D8: R1 | E8: Must | F8: Accept | G8: F-03 | H8: =IFERROR(INDEX(Features!$B$5:$B$33,MATCH(G8,Features!$A$5:$A$33,0)),"not mapped") -> Questions and confirmed facts | I8: TC-016, TC-017 | J8: requirements-R1-MVP_2026-10-27.md
A9: FR-06 | B9: Functional | C9: Generate a structured bill of materials (BOM) | D9: R1 | E9: Must | F9: Accept | G9: F-04 | H9: =IFERROR(INDEX(Features!$B$5:$B$33,MATCH(G9,Features!$A$5:$A$33,0)),"not mapped") -> Checked shopping list | I9: TC-012, TC-018, TC-019, TC-025, TC-080, TC-083, TC-084, TC-086, TC-096, TC-105, UT-10 | J9: requirements-R1-MVP_2026-10-27.md
A10: FR-07 | B10: Functional | C10: Reconcile suitable owned items against the BOM | D10: R1 | E10: Should | F10: Accept | G10: F-15 | H10: =IFERROR(INDEX(Features!$B$5:$B$33,MATCH(G10,Features!$A$5:$A$33,0)),"not mapped") -> Owned items on the shopping list | I10: TC-090 | J10: requirements-R1-MVP_2026-10-27.md | K10: Changed 29 Oct 2026
A11: FR-08 | B11: Functional | C11: Match exact catalogue products and variants | D11: R1 | E11: Must | F11: Accept | G11: F-04 | H11: =IFERROR(INDEX(Features!$B$5:$B$33,MATCH(G11,Features!$A$5:$A$33,0)),"not mapped") -> Checked shopping list | I11: TC-013, TC-020, TC-069, TC-088, UT-08, RT-07 | J11: requirements-R1-MVP_2026-10-27.md
A12: FR-09 | B12: Functional | C12: Validate product and component compatibility | D12: R1 | E12: Must | F12: Accept | G12: F-04 | H12: =IFERROR(INDEX(Features!$B$5:$B$33,MATCH(G12,Features!$A$5:$A$33,0)),"not mapped") -> Checked shopping list | I12: TC-013, TC-021, TC-088, UT-06 | J12: requirements-R1-MVP_2026-10-27.md
A13: FR-11 | B13: Functional | C13: Show price, availability and store information | D13: R1 | E13: Must | F13: Accept | G13: F-07 | H13: =IFERROR(INDEX(Features!$B$5:$B$33,MATCH(G13,Features!$A$5:$A$33,0)),"not mapped") -> Price, stock, aisle and shelf; referral if missing | I13: TC-022, TC-023, TC-024, TC-025, UT-10 | J13: requirements-R1-MVP_2026-10-27.md
A14: FR-15 | B14: Functional | C14: Present safety stops and escalation | D14: R1 | E14: Must | F14: Accept | G14: F-05 | H14: =IFERROR(INDEX(Features!$B$5:$B$33,MATCH(G14,Features!$A$5:$A$33,0)),"not mapped") -> Safety stops and hand-off | I14: TC-026, TC-082, TC-085, TC-086, TC-087, TC-089, TC-093, RT-01, RT-02, RT-03, RT-04 | J14: requirements-R1-MVP_2026-10-27.md
A15: FR-17 | B15: Functional | C15: Save the complete project list on the device – products, prices, section subtotals and total, items marked "I already have this", aisle and shelf (if a PLZ was given) and the OBI how-to links – so the customer can share it with anyone. | D15: R1 | E15: Must | F15: Accept | G15: F-16 | H15: =IFERROR(INDEX(Features!$B$5:$B$33,MATCH(G15,Features!$A$5:$A$33,0)),"not mapped") -> Save the project list | I15: TC-100 | J15: requirements-R1-MVP_2026-10-27.md | K15: Changed 29 Oct 2026
A16: FR-25 | B16: Functional | C16: Describe the project using speech (speech-to-text, German/English); the transcript is shown as editable text and confirmed before use | D16: R1 | E16: Must | F16: – | G16: F-02 | H16: =IFERROR(INDEX(Features!$B$5:$B$33,MATCH(G16,Features!$A$5:$A$33,0)),"not mapped") -> Describe the project by speaking | I16: TC-005, TC-006, TC-007, TC-008, TC-052, TC-056, TC-064, RT-08 | J16: requirements-R1-MVP_2026-10-27.md
A17: FR-27 | B17: Functional | C17: Classify project intent from speech input and extract candidate project description | D17: R1 | E17: Must | F17: – | G17: F-02 | H17: =IFERROR(INDEX(Features!$B$5:$B$33,MATCH(G17,Features!$A$5:$A$33,0)),"not mapped") -> Describe the project by speaking | I17: TC-005, TC-006, TC-008 | J17: requirements-R1-MVP_2026-10-27.md
A18: FR-29 | B18: Functional | C18: Optionally enter a German postcode (PLZ, 5 digits) at the start; the app lists the sample OBI stores sorted by distance (nearest first) and the customer chooses one; a store is never selected automatically (SR-06, RB-16); the chosen store is shown with a "change" option. The PLZ is processed on the device only. Invalid PLZ or no store within range → message plus full store list. | D18: R1 | E18: Should | F18: – | G18: F-06 | H18: =IFERROR(INDEX(Features!$B$5:$B$33,MATCH(G18,Features!$A$5:$A$33,0)),"not mapped") -> Optional postcode (PLZ) and store choice | I18: TC-009, TC-010, TC-011, TC-055, TC-078, TC-107, UT-02, UT-03 | J18: requirements-R1-MVP_2026-10-27.md | K18: Changed 29 Oct 2026
A19: FR-30 | B19: Functional | C19: Provide the complete, checked shopping list without a PLZ; aisle and shelf are shown as "not available" with a hint to add a PLZ. Product selection, compatibility and safety checks are identical with or without a PLZ. Without a store the catalogue price (sample value) is shown; stock, aisle and shelf are shown as "not available". | D19: R1 | E19: Must | F19: – | G19: F-06 | H19: =IFERROR(INDEX(Features!$B$5:$B$33,MATCH(G19,Features!$A$5:$A$33,0)),"not mapped") -> Optional postcode (PLZ) and store choice | I19: TC-012, TC-013, TC-053, UT-12 | J19: requirements-R1-MVP_2026-10-27.md | K19: Changed 29 Oct 2026
A20: FR-31 | B20: Functional | C20: If a list item is out of stock (qty 0) or not carried (no aisle) in the selected store, it stays on the list marked "not available here", and the app names the nearest other sample store that has it in stock (distance from the entered PLZ). If no store has it → "please ask staff". No automatic substitution. | D20: R1 | E20: Must | F20: – | G20: F-07 | H20: =IFERROR(INDEX(Features!$B$5:$B$33,MATCH(G20,Features!$A$5:$A$33,0)),"not mapped") -> Price, stock, aisle and shelf; referral if missing | I20: TC-024, TC-079 | J20: requirements-R1-MVP_2026-10-27.md
A21: FR-32 | B21: Functional | C21: Show the how-to links that the team checked for a project (video or article), as links only; https and allow-listed hosts only; German-only content is labelled in English mode | D21: R1 | E21: Should | F21: Proposed | G21: F-12 | H21: =IFERROR(INDEX(Features!$B$5:$B$33,MATCH(G21,Features!$A$5:$A$33,0)),"not mapped") -> OBI how-to links | I21: TC-092 | J21: requirements-R1-MVP_2026-10-27.md
A22: FR-33 | B22: Functional | C22: Ask for defects of used load-bearing items (cracks, swollen chipboard, bent metal, missing parts); a reported defect means the part must be replaced: it stays on the list and the customer sees a replace note | D22: R1 | E22: Must | F22: Proposed | G22: F-13 | H22: =IFERROR(INDEX(Features!$B$5:$B$33,MATCH(G22,Features!$A$5:$A$33,0)),"not mapped") -> Weight and condition check | I22: TC-091 | J22: requirements-R1-MVP_2026-10-27.md
A23: FR-34 | B23: Functional | C23: Each section of the list (Materials, Tools, Safety gear) shows its subtotal; the subtotals and the total drop by the price of an item marked "I already have this" and rise again when it is restored. | D23: R1 | E23: Should | F23: Accept | G23: F-15 | H23: =IFERROR(INDEX(Features!$B$5:$B$33,MATCH(G23,Features!$A$5:$A$33,0)),"not mapped") -> Owned items on the shopping list | I23: TC-090, TC-102 | J23: requirements-R1-MVP_2026-10-27.md | K23: Changed 29 Oct 2026
A24: SR-01 | B24: Safety | C24: Separate textual guesses from user-confirmed facts and manufacturer-supported specifications. | D24: R1 | E24: Must | F24: Discuss | G24: F-03 | H24: =IFERROR(INDEX(Features!$B$5:$B$33,MATCH(G24,Features!$A$5:$A$33,0)),"not mapped") -> Questions and confirmed facts | I24: TC-014, TC-027, UT-01 | J24: requirements-R1-MVP_2026-10-27.md
A25: SR-02 | B25: Safety | C25: Never certify wall type, allowable load, concealed services or safe drilling locations. A detector's negative result is not clearance to drill. | D25: R1 | E25: Must | F25: Discuss | G25: F-05 | H25: =IFERROR(INDEX(Features!$B$5:$B$33,MATCH(G25,Features!$A$5:$A$33,0)),"not mapped") -> Safety stops and hand-off | I25: TC-028, TC-034 | J25: requirements-R1-MVP_2026-10-27.md
A26: SR-03 | B26: Safety | C26: Require confirmed substrate, fixing system, bracket geometry, intended loading and applicable installation conditions before a final mounting recommendation. | D26: R1 | E26: Must | F26: – | G26: F-04 | H26: =IFERROR(INDEX(Features!$B$5:$B$33,MATCH(G26,Features!$A$5:$A$33,0)),"not mapped") -> Checked shopping list | I26: TC-012, TC-029, TC-030, TC-032, TC-045, TC-080, TC-089, UT-04 | J26: requirements-R1-MVP_2026-10-27.md
A27: SR-04 | B27: Safety | C27: Do not calculate shelf capacity by adding nominal anchor ratings; rely on applicable system evidence or refer to a qualified person. | D27: R1 | E27: Must | F27: – | G27: F-04 | H27: =IFERROR(INDEX(Features!$B$5:$B$33,MATCH(G27,Features!$A$5:$A$33,0)),"not mapped") -> Checked shopping list | I27: TC-031, TC-087, UT-05 | J27: requirements-R1-MVP_2026-10-27.md
A28: SR-05 | B28: Safety | C28: Describe detector capabilities and limitations for relevant hazards; do not imply every detector finds every pipe, especially plastic pipes. | D28: R1 | E28: Must | F28: – | G28: F-05 | H28: =IFERROR(INDEX(Features!$B$5:$B$33,MATCH(G28,Features!$A$5:$A$33,0)),"not mapped") -> Safety stops and hand-off | I28: TC-033, TC-034 | J28: requirements-R1-MVP_2026-10-27.md
A29: SR-06 | B29: Safety | C29: Inconclusive or missing evidence triggers a stop, not permission to proceed. | D29: R1 | E29: Must | F29: – | G29: F-03 | H29: =IFERROR(INDEX(Features!$B$5:$B$33,MATCH(G29,Features!$A$5:$A$33,0)),"not mapped") -> Questions and confirmed facts | I29: TC-004, TC-010, TC-017, TC-030, TC-032, TC-035, TC-044, TC-085, TC-094, UT-04, RT-05 | J29: requirements-R1-MVP_2026-10-27.md
A30: SR-07 | B30: Safety | C30: Preserve manufacturer warnings, installation conditions and approved combinations; generated text cannot weaken them. | D30: R1 | E30: Must | F30: – | G30: F-04 | H30: =IFERROR(INDEX(Features!$B$5:$B$33,MATCH(G30,Features!$A$5:$A$33,0)),"not mapped") -> Checked shopping list | I30: TC-036, TC-037, TC-045, UT-11, RT-06 | J30: requirements-R1-MVP_2026-10-27.md
A31: SR-08 | B31: Safety | C31: Re-run safety and compatibility checks after changes to material, dimensions, load or product. | D31: R1 | E31: Must | F31: – | G31: F-04 | H31: =IFERROR(INDEX(Features!$B$5:$B$33,MATCH(G31,Features!$A$5:$A$33,0)),"not mapped") -> Checked shopping list | I31: TC-038, TC-039, UT-07 | J31: requirements-R1-MVP_2026-10-27.md
A32: SR-09 | B32: Safety | C32: Exclude high-risk work from the supported flow and provide an appropriate professional hand-off. | D32: R1 | E32: Must | F32: – | G32: F-05 | H32: =IFERROR(INDEX(Features!$B$5:$B$33,MATCH(G32,Features!$A$5:$A$33,0)),"not mapped") -> Safety stops and hand-off | I32: TC-026, TC-040, TC-041, TC-042, TC-044, TC-095, RT-01, RT-02, RT-03, RT-04, RT-08 | J32: requirements-R1-MVP_2026-10-27.md
A33: SR-10 | B33: Safety | C33: Qualified reviewers approve project templates and release-blocking test cases before public mounting guidance. | D33: R1 | E33: Should | F33: – | G33: F-08 | H33: =IFERROR(INDEX(Features!$B$5:$B$33,MATCH(G33,Features!$A$5:$A$33,0)),"not mapped") -> Sample data and team review | I33: TC-043, TC-099 | J33: requirements-R1-MVP_2026-10-27.md
A34: SR-11 | B34: Safety | C34: Separate speech guesses from user-confirmed facts and manufacturer-supported specifications. | D34: R1 | E34: Must | F34: – | G34: F-02 | H34: =IFERROR(INDEX(Features!$B$5:$B$33,MATCH(G34,Features!$A$5:$A$33,0)),"not mapped") -> Describe the project by speaking | I34: TC-007, TC-027, UT-01 | J34: requirements-R1-MVP_2026-10-27.md
A35: SR-13 | B35: Safety | C35: Stop when a load or a size is above the limit of the project for the confirmed wall type or object (limits from the project catalogue, sheet Limits; limits are for the whole object, never per plug). Size stops name the part, the needed size and the available catalogue sizes in the unit of the question. | D35: R1 | E35: Must | F35: Proposed | G35: F-11 | H35: =IFERROR(INDEX(Features!$B$5:$B$33,MATCH(G35,Features!$A$5:$A$33,0)),"not mapped") -> Project catalogue: 9 projects with limits and stop rules | I35: TC-081, TC-082, TC-083, TC-085, TC-086, TC-087, TC-088, TC-089, TC-093, TC-096, TC-097, TC-105, TC-106 | J35: requirements-R1-MVP_2026-10-27.md | K35: Changed 29 Oct 2026
A36: SR-14 | B36: Safety | C36: Without a known load the worst case is assumed; if the worst case is above the limit, stop and ask to weigh the item or ask staff. | D36: R1 | E36: Must | F36: Accept | G36: F-13 | H36: =IFERROR(INDEX(Features!$B$5:$B$33,MATCH(G36,Features!$A$5:$A$33,0)),"not mapped") -> Weight and condition check | I36: TC-094, TC-104 | J36: requirements-R1-MVP_2026-10-27.md | K36: Changed 29 Oct 2026
A37: SR-15 | B37: Safety | C37: Owned parts may replace list items only where the project allows it; wall plugs and screws are always new; an owned load-bearing part must be undamaged and rated for the whole load × 1.25 on its own; a used load-bearing part with a reported defect is never accepted. | D37: R1 | E37: Must | F37: Proposed | G37: F-15 | H37: =IFERROR(INDEX(Features!$B$5:$B$33,MATCH(G37,Features!$A$5:$A$33,0)),"not mapped") -> Owned items on the shopping list | I37: TC-090, TC-091 | J37: requirements-R1-MVP_2026-10-27.md | K37: Changed 29 Oct 2026
A38: SR-16 | B38: Safety | C38: At every safety level (also Basic) the high-risk filter, the catalogue check, the unchanged product warnings and the output check always run. | D38: R1 | E38: Must | F38: Proposed | G38: F-14 | H38: =IFERROR(INDEX(Features!$B$5:$B$33,MATCH(G38,Features!$A$5:$A$33,0)),"not mapped") -> One safety check per project | I38: TC-084, TC-095 | J38: requirements-R1-MVP_2026-10-27.md
A39: SR-17 | B39: Safety | C39: When a tool or a safety-gear item is marked "I already have this", the app shows the hint "Keep the right tool and gear to ensure safety." | D39: R1 | E39: Must | F39: Accept | G39: F-15 | H39: =IFERROR(INDEX(Features!$B$5:$B$33,MATCH(G39,Features!$A$5:$A$33,0)),"not mapped") -> Owned items on the shopping list | I39: TC-103 | J39: requirements-R1-MVP_2026-10-27.md | K39: Changed 29 Oct 2026
A40: NFR-01 | B40: Non-functional | C40: Mobile-first; core flow completable in under two minutes in usability testing without instructions. | D40: R1 | E40: Must | F40: Discuss | G40: F-10 | H40: =IFERROR(INDEX(Features!$B$5:$B$33,MATCH(G40,Features!$A$5:$A$33,0)),"not mapped") -> Mobile use, speed and language | I40: TC-046, TC-047 | J40: requirements-R1-MVP_2026-10-27.md
A41: NFR-02 | B41: Non-functional | C41: Catalogue lookup under one second; bounded MVP list generation under five seconds. For a multi-step pilot plan, show progress and target under 60 s at p95. | D41: R1 | E41: Should | F41: – | G41: F-10 | H41: =IFERROR(INDEX(Features!$B$5:$B$33,MATCH(G41,Features!$A$5:$A$33,0)),"not mapped") -> Mobile use, speed and language | I41: TC-048, TC-049 | J41: requirements-R1-MVP_2026-10-27.md
...

Sheet Documents
A1: Documents
A2: Paths in the team repository st854d2gpb-create/9_Applied-AI (main)
A4: Document | B4: File | C4: Content | D4: Status 28 Oct 2026
A5: Requirements R1 | B5: requirements/requirements-R1-MVP_2026-10-27.md | C5: 53 requirements (44 Must, 9 Should) | D5: Updated with the decisions of 29 Oct 2026
A6: Requirements R2–R4 | B6: requirements/requirements-R2-R4_2026-10-27.md | C6: 18 requirements | D6: Updated with the decisions of 29 Oct 2026
A7: Test cases | B7: test/01_test_cases_2026-10-27.md | C7: v1.2: TC-001…TC-107, UT-01…12, RT-01…08, 19 release gates; 97 automated tests PASS (27 Oct) | D7: Updated with the decisions of 29 Oct 2026; new tests NR
A8: Product catalogue | B8: data/product_catalogue.xlsx | C8: 105 products EN/DE, stock in 5 stores | D8: To update: OBI Schwabach (D-11), aerated-concrete plugs and wood screws (D-5)
A9: Project catalogue | B9: data/project_catalogue.xlsx | C9: 9 projects: questions, limits, items, stop rules, how-to links | D9: Draft; sliding-door rules to add (D-7), videos verified (D-9)
A10: App and templates | B10: app/ (templates in app/data/templates/) | C10: Web app, 9 project templates, automated tests | D10: Built
A11: Design | B11: data/03-design.md | C11: Architecture, components, rules | D11: v0.4 (25 Oct 2026) – outdated; update to v0.5 after the meeting (D-12)
A12: Change proposal | B12: docs/change-proposal-R1.md | C12: Built features and the team decisions D-1 … D-12 | D12: Decided 29 Oct 2026
A13: Feature implementation plan | B13: docs/Feature_Implementation_Plan.xlsx | C13: This file | D13: v0.9

Sheet Version history
A1: Version history
A2: Update this plan after every major team decision
A4: Version | B4: Date | C4: What changed
A5: 0.1–0.7 | B5: 26–27 Oct 2026 | C5: Earlier drafts based on the old requirement workbook.
A6: 0.8 | B6: 28 Oct 2026 | C6: New basis: requirements and test cases of 27 Oct 2026 (colleague, after vibe coding). Features renumbered F-01…F-29 and simplified. Status per feature (built / partly / not built). Discussion list D-1…D-12. F-16 Save the project list = R1 / Must (agreed).
A7: 0.8.1 | B7: 28 Oct 2026 | C7: Discussion list simplified to D-1…D-10: owned items and prices merged (D-3), wood and aerated concrete together (D-5), release tests and text updates explained, price without postcode = built (D-9), speech simplified (D-10), team review finalised (removed).
A8: 0.8.2 | B8: 28 Oct 2026 | C8: D-5 = wood and aerated concrete with full feature in R1 (else not offered); new D-11: allowed range shown beside each input field.
A9: 0.8.3 | B9: 28 Oct 2026 | C9: Speech removed from the discussion (works in Chrome, Edge, Safari, phones – checked by Hari). Range note = D-10. New D-11: OBI Schwabach as 6th store. New D-12: update the design document.
A10: 0.9 | B10: 29 Oct 2026 | C10: Team decisions D-1 … D-12 recorded (Discussion: decision, result, changed in). Basis: updated requirements (53 R1, 18 R2–R4) and test cases v1.2. F-15 gets FR-34, SR-17, RB-24; F-11 RB-22; F-14 RB-25.
